{"errorMessage":"An error occurred (UnrecognizedClientException) when calling the DescribeLogGroups operation: The security token included in the request is invalid.","errorType":"UnrecognizedClientException","stackTrace":["  File \"/Users/usman/Desktop/studd/ugLocalstack/localstack/localstack/services/awslambda/lambda_api.py\", line 568, in run_lambda\n    result = LAMBDA_EXECUTOR.execute(func_arn, func_details, event, context=context,\n","  File \"/Users/usman/Desktop/studd/ugLocalstack/localstack/localstack/services/awslambda/lambda_executors.py\", line 174, in execute\n    return do_execute()\n","  File \"/Users/usman/Desktop/studd/ugLocalstack/localstack/localstack/services/awslambda/lambda_executors.py\", line 166, in do_execute\n    return _run(func_arn=func_arn)\n","  File \"/Users/usman/Desktop/studd/ugLocalstack/localstack/localstack/utils/cloudwatch/cloudwatch_util.py\", line 149, in wrapped\n    raise e\n","  File \"/Users/usman/Desktop/studd/ugLocalstack/localstack/localstack/utils/cloudwatch/cloudwatch_util.py\", line 145, in wrapped\n    result = func(*args, **kwargs)\n","  File \"/Users/usman/Desktop/studd/ugLocalstack/localstack/localstack/services/awslambda/lambda_executors.py\", line 157, in _run\n    raise e\n","  File \"/Users/usman/Desktop/studd/ugLocalstack/localstack/localstack/services/awslambda/lambda_executors.py\", line 145, in _run\n    result = self._execute(func_arn, func_details, event, context, version)\n","  File \"/Users/usman/Desktop/studd/ugLocalstack/localstack/localstack/services/awslambda/lambda_executors.py\", line 795, in _execute\n    _store_logs(func_details, log_output)\n","  File \"/Users/usman/Desktop/studd/ugLocalstack/localstack/localstack/services/awslambda/lambda_executors.py\", line 90, in _store_logs\n    return store_cloudwatch_logs(log_group_name, log_stream_name, log_output, invocation_time)\n","  File \"/Users/usman/Desktop/studd/ugLocalstack/localstack/localstack/utils/cloudwatch/cloudwatch_util.py\", line 67, in store_cloudwatch_logs\n    log_groups = logs_client.describe_log_groups()['logGroups']\n","  File \"/Users/usman/Desktop/studd/ugLocalstack/localstack/.venv/lib/python3.8/site-packages/botocore/client.py\", line 357, in _api_call\n    return self._make_api_call(operation_name, kwargs)\n","  File \"/Users/usman/Desktop/studd/ugLocalstack/localstack/.venv/lib/python3.8/site-packages/botocore/client.py\", line 676, in _make_api_call\n    raise error_class(parsed_response, operation_name)\n"]}
